Timestamp: 2025-08-13 18:10:54.807154
Context: edit_profile view for user gmadde
Exception: table users_sociallink has no column named display_order

Traceback:
Traceback (most recent call last):
  File "C:\Users\Inphinithy\Documents\projects\Areis\aries_venv\Lib\site-packages\django\db\backends\utils.py", line 105, in _execute
    return self.cursor.execute(sql, params)
           ^^^^^^^^^^^^^^^^^^^^^^^^^^^^^^^^
  File "C:\Users\Inphinithy\Documents\projects\Areis\aries_venv\Lib\site-packages\django\db\backends\sqlite3\base.py", line 354, in execute
    return super().execute(query, params)
           ^^^^^^^^^^^^^^^^^^^^^^^^^^^^^^
sqlite3.OperationalError: table users_sociallink has no column named display_order

The above exception was the direct cause of the following exception:

Traceback (most recent call last):
  File "C:\Users\Inphinithy\Documents\projects\Areis\aries\users\views.py", line 238, in edit_profile
    social_formset.save()
  File "C:\Users\Inphinithy\Documents\projects\Areis\aries_venv\Lib\site-packages\django\forms\models.py", line 796, in save
    return self.save_existing_objects(commit) + self.save_new_objects(commit)
                                                ^^^^^^^^^^^^^^^^^^^^^^^^^^^^^
  File "C:\Users\Inphinithy\Documents\projects\Areis\aries_venv\Lib\site-packages\django\forms\models.py", line 959, in save_new_objects
    self.new_objects.append(self.save_new(form, commit=commit))
                            ^^^^^^^^^^^^^^^^^^^^^^^^^^^^^^^^^^
  File "C:\Users\Inphinithy\Documents\projects\Areis\aries_venv\Lib\site-packages\django\forms\models.py", line 1157, in save_new
    return super().save_new(form, commit=commit)
           ^^^^^^^^^^^^^^^^^^^^^^^^^^^^^^^^^^^^^
  File "C:\Users\Inphinithy\Documents\projects\Areis\aries_venv\Lib\site-packages\django\forms\models.py", line 769, in save_new
    return form.save(commit=commit)
           ^^^^^^^^^^^^^^^^^^^^^^^^
  File "C:\Users\Inphinithy\Documents\projects\Areis\aries_venv\Lib\site-packages\django\forms\models.py", line 554, in save
    self.instance.save()
  File "C:\Users\Inphinithy\Documents\projects\Areis\aries_venv\Lib\site-packages\django\db\models\base.py", line 892, in save
    self.save_base(
  File "C:\Users\Inphinithy\Documents\projects\Areis\aries_venv\Lib\site-packages\django\db\models\base.py", line 998, in save_base
    updated = self._save_table(
              ^^^^^^^^^^^^^^^^^
  File "C:\Users\Inphinithy\Documents\projects\Areis\aries_venv\Lib\site-packages\django\db\models\base.py", line 1161, in _save_table
    results = self._do_insert(
              ^^^^^^^^^^^^^^^^
  File "C:\Users\Inphinithy\Documents\projects\Areis\aries_venv\Lib\site-packages\django\db\models\base.py", line 1202, in _do_insert
    return manager._insert(
           ^^^^^^^^^^^^^^^^
  File "C:\Users\Inphinithy\Documents\projects\Areis\aries_venv\Lib\site-packages\django\db\models\manager.py", line 87, in manager_method
    return getattr(self.get_queryset(), name)(*args, **kwargs)
           ^^^^^^^^^^^^^^^^^^^^^^^^^^^^^^^^^^^^^^^^^^^^^^^^^^^
  File "C:\Users\Inphinithy\Documents\projects\Areis\aries_venv\Lib\site-packages\django\db\models\query.py", line 1847, in _insert
    return query.get_compiler(using=using).execute_sql(returning_fields)
           ^^^^^^^^^^^^^^^^^^^^^^^^^^^^^^^^^^^^^^^^^^^^^^^^^^^^^^^^^^^^^
  File "C:\Users\Inphinithy\Documents\projects\Areis\aries_venv\Lib\site-packages\django\db\models\sql\compiler.py", line 1836, in execute_sql
    cursor.execute(sql, params)
  File "C:\Users\Inphinithy\Documents\projects\Areis\aries_venv\Lib\site-packages\django\db\backends\utils.py", line 122, in execute
    return super().execute(sql, params)
           ^^^^^^^^^^^^^^^^^^^^^^^^^^^^
  File "C:\Users\Inphinithy\Documents\projects\Areis\aries_venv\Lib\site-packages\django\db\backends\utils.py", line 79, in execute
    return self._execute_with_wrappers(
           ^^^^^^^^^^^^^^^^^^^^^^^^^^^^
  File "C:\Users\Inphinithy\Documents\projects\Areis\aries_venv\Lib\site-packages\django\db\backends\utils.py", line 92, in _execute_with_wrappers
    return executor(sql, params, many, context)
           ^^^^^^^^^^^^^^^^^^^^^^^^^^^^^^^^^^^^
  File "C:\Users\Inphinithy\Documents\projects\Areis\aries_venv\Lib\site-packages\django\db\backends\utils.py", line 100, in _execute
    with self.db.wrap_database_errors:
  File "C:\Users\Inphinithy\Documents\projects\Areis\aries_venv\Lib\site-packages\django\db\utils.py", line 91, in __exit__
    raise dj_exc_value.with_traceback(traceback) from exc_value
  File "C:\Users\Inphinithy\Documents\projects\Areis\aries_venv\Lib\site-packages\django\db\backends\utils.py", line 105, in _execute
    return self.cursor.execute(sql, params)
           ^^^^^^^^^^^^^^^^^^^^^^^^^^^^^^^^
  File "C:\Users\Inphinithy\Documents\projects\Areis\aries_venv\Lib\site-packages\django\db\backends\sqlite3\base.py", line 354, in execute
    return super().execute(query, params)
           ^^^^^^^^^^^^^^^^^^^^^^^^^^^^^^
django.db.utils.OperationalError: table users_sociallink has no column named display_order

